Workbook

Sheet Supuestos
A1: LUMETRIQ Reflejo Fijo · Supuestos del modelo económico (MXN sin IVA)
A2: Azul = dato que se puede cambiar · Negro = fórmula · Verde = viene de otra hoja · Amarillo = supuesto clave por validar. Fecha de consulta: 22 de octubre de 2026.
A3: Parámetro | B3: Valor | C3: Unidad | D3: Fuente / etiqueta
A4: Generales
A5: Tipo de cambio | B5: 18.7 | C5: MXN/USD | D5: Banxico, FIX del 22/10/2026 = 18.7005 [Confirmado]
A6: Pods por kit Studio | B6: 4 | C6: pods | D6: Modelo de ingresos de la semana 7
A7: Gimnasios nuevos en el año 1 | B7: 10 | C7: gimnasios | D7: Plan conservador (SOM semana 4: 15) [Hipótesis]
A8: Gimnasios nuevos en el año 2 | B8: 25 | C8: gimnasios | D8: 100 pods en el año 2 (SOM semana 4: 30) [Hipótesis]
A9: Incluir ADXL375 en el BOM (1 = sí, 0 = versión Reacción) | B9: 1 | C9: 1/0 | D9: Palanca de costo: sin ADXL375 la fuerza la siguen midiendo las celdas
A10: Mano de obra
A11: Salario promedio mensual, ingeniería en electrónica y automatización | B11: 25203 | C11: MXN/mes | D11: IMCO Compara Carreras (Luz Noticias 25/08/2026; Expansión 08/02/2026) [Confirmado]
A12: Horas trabajadas por semana (ingenieros) | B12: 40.3 | C12: h/sem | D12: Data México, ENOE 2026-T1, ingenieros electrónicos [Confirmado]
A13: Factor de costo patronal | B13: 1.35 | C13: x | D13: IMSS, INFONAVIT, SAR, aguinaldo, prima vacacional, impuesto sobre nómina; rango 1.30–1.40 [Estimado]
A14: Costo por hora de ingeniería | B14: =ROUND(B11/(B12*52/12)*B13,0) -> 195 | C14: MXN/h | D14: Fórmula: salario / horas al mes × factor
A15: Costo por hora de técnico (ensamble y soporte) | B15: 80 | C15: MXN/h | D15: ≈ $10,300/mes de salario con factor 1.35; arriba del promedio de técnicos en electrónica de Data México (≈ $7k) [Estimado]
A16: Horas de ensamble, calibración y prueba por pod (lote de 10) | B16: 1.5 | C16: h/pod | D16: RR-01 del PDS v1.0 (≤ 1.5 h)
A17: Horas de ensamble por pod (lote de 100) | B17: 1 | C17: h/pod | D17: Con plantillas y práctica [Estimado]
A18: Persona a medio tiempo (escenario B) | B18: 20 | C18: h/sem | D18: Ventas y soporte [Hipótesis]
A19: Costeo
A20: Empaque por kit (lote de 10) | B20: 160 | C20: MXN/kit | D20: Caja + espuma [Estimado]
A21: Empaque por kit (lote de 100) | B21: 100 | C21: MXN/kit | D21: [Estimado]
A22: Overhead (indirectos) | B22: 0.15 | C22: % del costo directo | D22: Método de la clase (10–20 %)
A23: Contingencias en costo unitario | B23: 0.25 | C23: % del costo directo | D23: Prompt de la semana (25 %)
A24: Margen cost-plus | B24: 0.4 | C24: % | D24: Prompt de la semana (40 %)
A25: Costo financiero si se subsidia el hardware | B25: 0.2 | C25: % anual | D25: Ejemplo de la clase (20 %)
A26: Nube e IA
A27: Supabase Pro | B27: 25 | C27: USD/mes | D27: supabase.com/pricing, consultado 22/10/2026 [Confirmado]
A28: Tokens de entrada por llamada | B28: 600 | C28: tokens | D28: Prompt real de 1,471 caracteres + JSON + 30 % por tokenizador nuevo [Estimado por Claude]
A29: Tokens de salida por llamada | B29: 250 | C29: tokens | D29: Respuesta de ≤ 120 palabras con margen [Estimado]
A30: Precio de entrada, Claude Haiku 5.5 | B30: 0.1 | C30: USD/millón | D30: claude.com/pricing, 22/10/2026, prompts ≤ 100K tokens [Confirmado]
A31: Precio de salida, Claude Haiku 5.5 | B31: 0.5 | C31: USD/millón | D31: claude.com/pricing, 22/10/2026 [Confirmado]
A32: Precio de entrada, Claude Sonnet 5.5 (comparación) | B32: 2 | C32: USD/millón | D32: claude.com/pricing [Confirmado]
A33: Precio de salida, Claude Sonnet 5.5 (comparación) | B33: 10 | C33: USD/millón | D33: claude.com/pricing [Confirmado]
A34: Sesiones con resumen de IA por gimnasio al día | B34: 40 | C34: sesiones/día | D34: Gimnasio con ≈ 40 alumnos activos al día [Hipótesis]
A35: Días por mes | B35: 30 | C35: días | D35: Fórmula de la clase
A36: Reintentos por verificador de cifras | B36: 0.1 | C36: % | D36: [Estimado]
A37: Precios y cobro
A38: Precio del kit Studio (4 pods + placas + estuche) | B38: 13490 | C38: MXN | D38: Recomendado en el paso 2
A39: Suscripción Studio por sede | B39: 499 | C39: MXN/mes | D39: Recomendado en el paso 2
A40: Meses gratis antes de cobrar la suscripción | B40: 1 | C40: mes | D40: Muro al final del primer mes (modelo de ingresos)
...

Sheet BOM
A1: BOM por pod · precios reales cotizados (MXN sin IVA)
A2: Las columnas USD se convierten con el tipo de cambio de Supuestos. Un precio en MXN azul es cotización local; uno negro sale de la fórmula USD × tipo de cambio.
A3: # | B3: Componente | C3: Especificación | D3: Proveedor / tiempo de entrega | E3: USD a 10 | F3: MXN a 10 | G3: USD a 100 | H3: MXN a 100 | I3: Parte del BOM a 10 | J3: Fuente y etiqueta
A4: 1 | B4: ESP32-WROOM-32E-N4 (módulo) | C4: Wi-Fi + BLE 5, 4 MB flash, módulo castelado 1.27 mm | D4: LCSC / JLCPCB C701341 · 5–10 días | E4: 3.24 | F4: =ROUND(E4*Supuestos!$B$5,0) -> 61 | G4: 2.95 | H4: =ROUND(G4*Supuestos!$B$5,0) -> 55 | I4: =F4/$F$19 -> 0.041581459 | J4: Sem. 5: $60 a 18.5 → USD 3.24 [Confirmado sem. 5]; a 100 [Estimado]
A5: 2 | B5: ADXL375BCCZ (CI, ensamblado por JLCPCB) | C5: Acelerómetro ±200 g, LGA-14, SPI | D5: LCSC / JLCPCB C662206 · 5–10 días | E5: 22.7315 | F5: =ROUND(E5*Supuestos!$B$5,0)*Supuestos!$B$9 -> 425 | G5: 19.2744 | H5: =ROUND(G5*Supuestos!$B$5,0)*Supuestos!$B$9 -> 360 | I5: =F5/$F$19 -> 0.28970688 | J5: LCSC 22/10/2026: USD 22.7315 (10+), 19.2744 (100+), 64 en inventario [Confirmado]
A6: 3 | B6: ADS1220IPWR | C6: ADC 24 bits, 2 kSPS, PGA ×128, TSSOP-16 | D6: Unit Electronics · 1–3 días | F6: 95 | H6: 80 | I6: =F6/$F$19 -> 0.06475801 | J6: Unit $95.40 (outlet) [Confirmado sem. 5]; a 100 por LCSC [Estimado]
A7: 4 | B7: 4 celdas de carga 50 kg SEN-10245 | C7: Medio puente, 34 × 34 × 7 mm, 1.0 mV/V | D7: Unit Electronics · 1–3 días | F7: 60 | H7: 60 | I7: =F7/$F$19 -> 0.040899796 | J7: 4 × $14.97 (precio 35+) [Confirmado sem. 5]
A8: 5 | B8: Pasivos, TP4056/MCP73831, AP2112K, USB-C, TVS, fusible, JST-PH, Hall | C8: 0603 o mayor, pitch ≥ 0.8 mm | D8: Unit / LCSC · 1–10 días | F8: 70 | H8: 55 | I8: =F8/$F$19 -> 0.047716428 | J8: [Estimado]
A9: 6 | B9: Arco de 18 LED WS2812B + difusor | C9: Tira 144 LED/m en 3 tramos de 6; difusor PETG | D9: Unit / Mercado Libre · 1–5 días | F9: 60 | H9: 48 | I9: =F9/$F$19 -> 0.040899796 | J9: [Estimado]
A10: 7 | B10: Celda 18650 protegida con pestañas | C10: ≥ 2,000 mAh, con PCM | D10: Steren / Mercado Libre · 1–5 días | F10: 150 | H10: 120 | I10: =F10/$F$19 -> 0.10224949 | J10: [Estimado]
A11: 8 | B11: Conector pogo magnético (frontal y trasero) | C11: Rehundido a las 6 en punto | D11: Amazon MX / Mercado Libre · 2–7 días | F11: 80 | H11: 60 | I11: =F11/$F$19 -> 0.054533061 | J11: [Estimado]
A12: 9 | B12: PCB de 2 capas + ensamble parcial (2 CI Extended) | C12: Prorrateado con envío | D12: JLCPCB · 7–12 días | E12: 4.86 | F12: =ROUND(E12*Supuestos!$B$5,0) -> 91 | G12: 2.41 | H12: =ROUND(G12*Supuestos!$B$5,0) -> 45 | I12: =F12/$F$19 -> 0.062031357 | J12: Sem. 5: $90 a 18.5 → USD 4.86 [Estimado]
A13: 10 | B13: Plato flotante de aluminio 6061-T6 | C13: Ø 118 × 3 mm, ≈ 89 g | D13: Taller de corte local · 3–7 días | F13: 80 | H13: 55 | I13: =F13/$F$19 -> 0.054533061 | J13: [Estimado]
A14: 11 | B14: Topes M4, tornillos de hombro, insertos de latón, arandelas, fijador | C14: M3/M4, fijador medio | D14: Ferretería / Unit · 1–3 días | F14: 60 | H14: 45 | I14: =F14/$F$19 -> 0.040899796 | J14: [Estimado]
A15: 12 | B15: Carcasa PETG/ASA (cuerpo, labio, tapa, aro tensor) | C15: Ø 160 × 75 mm, ≈ 320 g | D15: Filamento Unit / Amazon MX · 1–5 días | F15: 115 | H15: 105 | I15: =F15/$F$19 -> 0.078391275 | J15: [Estimado]
A16: 13 | B16: Pad Ø 120: vinipiel + EVA en 2 capas + diafragma | C16: Cóncavo, flecha ≈ 4 mm | D16: Tapicería / EVA / refaccionaria · mismo día | F16: 55 | H16: 42 | I16: =F16/$F$19 -> 0.037491479 | J16: [Estimado]
A17: 14 | B17: Burlete EPDM + botón | C17: Mitad frontal del canto | D17: Ferretería / Unit · mismo día | F17: 20 | H17: 15 | I17: =F17/$F$19 -> 0.013633265 | J17: [Estimado]
A18: 15 | B18: Placa de pared Ø 120 | C18: MDF o acrílico de 6 mm, corte láser | D18: Corte láser local · 2–5 días | F18: 45 | H18: 28 | I18: =F18/$F$19 -> 0.030674847 | J18: [Estimado]
B19: BOM por pod | D19: Entrega del lote completo: ≤ 12 días | F19: =SUM(F4:F18) -> 1467 | H19: =SUM(H4:H18) -> 1173 | I19: =SUM(I4:I18) -> 1
B20: Cambio a 100 unidades | H20: =H19/F19-1 -> -0.200409
B21: BOM × 10 pods (compra del lote) | F21: =F19*10 -> 14670

Sheet Costo unitario
A1: Paso 1 · Costo unitario real por pod
A3: Concepto | B3: A 10 pods | C3: A 100 pods | D3: Fórmula
A4: BOM | B4: =BOM!$F$19 -> 1467 | C4: =BOM!$H$19 -> 1173 | D4: Hoja BOM
A5: Ensamble, calibración y prueba | B5: =Supuestos!$B$16*Supuestos!$B$15 -> 120 | C5: =Supuestos!$B$17*Supuestos!$B$15 -> 80 | D5: horas por pod × costo por hora de técnico
A6: Empaque | B6: =Supuestos!$B$20/Supuestos!$B$6 -> 40 | C6: =Supuestos!$B$21/Supuestos!$B$6 -> 25 | D6: empaque por kit ÷ 4
A7: Costo directo | B7: =SUM(B4:B6) -> 1627 | C7: =SUM(C4:C6) -> 1278 | D7: BOM + ensamble + empaque
A8: Overhead | B8: =B7*Supuestos!$B$22 -> 244.05 | C8: =C7*Supuestos!$B$22 -> 191.7 | D8: 15 % del directo
A9: Contingencias | B9: =B7*Supuestos!$B$23 -> 406.75 | C9: =C7*Supuestos!$B$23 -> 319.5 | D9: 25 % del directo
A10: Costo del hardware por pod | B10: =B7+B8+B9 -> 2277.8 | C10: =C7+C8+C9 -> 1789.2 | D10: directo + overhead + contingencias
A11: Porción de nube (12 meses) | B11: =Supuestos!$B$27*Supuestos!$B$5*12/(Supuestos!$B$7*Supuestos!$B$6) -> 140.25 | C11: =Supuestos!$B$27*Supuestos!$B$5*12/(Supuestos!$B$8*Supuestos!$B$6) -> 56.1 | D11: Supabase × tipo de cambio × 12 ÷ pods del año
A12: Porción de IA (12 meses) | B12: =IA!$B$9*12/Supuestos!$B$6 -> 13.69962 | C12: =IA!$B$9*12/Supuestos!$B$6 -> 13.69962 | D12: IA por gimnasio × 12 ÷ 4 pods
A13: Costo unitario total del primer año | B13: =B10+B11+B12 -> 2431.7496 | C13: =C10+C11+C12 -> 1858.9996 | D13: hardware + nube + IA
A14: Costo del kit de 4 (solo hardware) | B14: =B10*Supuestos!$B$6 -> 9111.2 | C14: =C10*Supuestos!$B$6 -> 7156.8 | D14: 4 × costo del hardware
A15: ADXL375 como % del BOM | B15: =BOM!$F$5/B4 -> 0.28970688 | C15: =BOM!$H$5/C4 -> 0.30690537 | D15: componente de mayor costo
A16: ADXL375 como % del costo unitario | B16: =BOM!$F$5/B13 -> 0.17477128 | C16: =BOM!$H$5/C13 -> 0.19365254
A17: IA como % del costo unitario | B17: =B12/B13 -> 0.0056336474 | C17: =C12/C13 -> 0.0073693506
A18: Nube como % del costo unitario | B18: =B11/B13 -> 0.057674523 | C18: =C11/C13 -> 0.030177521

Sheet IA
A1: Costo mensual de la IA · fórmula de la clase con tokens medidos
A3: Concepto | B3: Valor | C3: Fórmula
A4: Llamadas al mes por gimnasio | B4: =Supuestos!$B$34*Supuestos!$B$35*(1+Supuestos!$B$36) -> 1320 | C4: sesiones/día × 30 × (1 + reintentos)
A5: Costo de entrada por llamada (USD) | B5: =Supuestos!$B$28*Supuestos!$B$30/1000000 -> 6e-05 | C5: tokens de entrada × precio / 1,000,000
A6: Costo de salida por llamada (USD) | B6: =Supuestos!$B$29*Supuestos!$B$31/1000000 -> 0.000125 | C6: tokens de salida × precio / 1,000,000
A7: Costo por llamada (USD) | B7: =B5+B6 -> 0.000185 | C7: entrada + salida
A8: Costo mensual por gimnasio (USD) | B8: =B7*B4 -> 0.2442 | C8: costo por llamada × llamadas al mes
A9: Costo mensual por gimnasio (MXN) | B9: =B8*Supuestos!$B$5 -> 4.56654 | C9: USD × tipo de cambio
A10: Costo mensual por pod (MXN) | B10: =B9/Supuestos!$B$6 -> 1.141635 | C10: por gimnasio ÷ 4 pods
A11: Costo mensual por usuario individual con 2 sesiones al día (MXN) | B11: =B7*2*Supuestos!$B$35*(1+Supuestos!$B$36)*Supuestos!$B$5 -> 0.228327 | C11: 2 llamadas/día × 30 × 1.1 × costo × tipo de cambio
A12: IA como % de la suscripción | B12: =B9/Supuestos!$B$39 -> 0.0091513828 | C12: costo mensual ÷ precio de la suscripción
A13: Mismo uso con Sonnet 5.5 (MXN/mes por gimnasio) | B13: =(Supuestos!$B$28*Supuestos!$B$32+Supuestos!$B$29*Supuestos!$B$33)/1000000*B4*Supuestos!$B$5 -> 91.3308 | C13: mismos tokens con precios de Sonnet
A14: Sonnet como % de la suscripción | B14: =B13/Supuestos!$B$39 -> 0.18302766
A15: Costo anual de la IA con los gimnasios del año 1 (MXN) | B15: =B9*12*Supuestos!$B$7 -> 547.9848 | C15: por gimnasio × 12 × gimnasios (cota superior: todos activos 12 meses)

Sheet Precio
A1: Paso 2 · Precio de venta: piso cost-plus, techo value-based y recomendado
A3: Concepto | B3: A 10 | C3: A 100 | D3: Fórmula
A4: Cost-plus del kit (piso) | B4: ='Costo unitario'!$B$14*(1+Supuestos!$B$24) -> 12755.68 | C4: ='Costo unitario'!$C$14*(1+Supuestos!$B$24) -> 10019.52 | D4: costo del kit × 1.40
A5: Suscripción · nube por gimnasio | B5: =Supuestos!$B$27*Supuestos!$B$5/Supuestos!$B$7 -> 46.75 | C5: =Supuestos!$B$27*Supuestos!$B$5/Supuestos!$B$8 -> 18.7 | D5: Supabase ÷ gimnasios
A6: Suscripción · IA por gimnasio | B6: =IA!$B$9 -> 4.56654 | C6: =IA!$B$9 -> 4.56654 | D6: hoja IA
A7: Suscripción · soporte | B7: =Supuestos!$B$46*Supuestos!$B$15 -> 80 | C7: =Supuestos!$B$46*Supuestos!$B$15 -> 80 | D7: h/mes × costo por hora de técnico
A8: Suscripción · fundas de repuesto | B8: =Supuestos!$B$48*Supuestos!$B$47/3 -> 13.333333 | C8: =Supuestos!$B$48*Supuestos!$B$47/3 -> 13.333333 | D8: 4 fundas × $10 cada 3 meses
A9: Costo operativo mensual por gimnasio | B9: =SUM(B5:B8) -> 144.64987 | C9: =SUM(C5:C8) -> 116.59987 | D9: suma
A10: Piso de la suscripción (cost-plus, incluye comisión) | B10: =(1+Supuestos!$B$24)*(B9+Supuestos!$B$42*(1+Supuestos!$B$43))/(1-(1+Supuestos!$B$24)*Supuestos!$B$41*(1+Supuestos!$B$43)) -> 221.56351 | C10: =(1+Supuestos!$B$24)*(C9+Supuestos!$B$42*(1+Supuestos!$B$43))/(1-(1+Supuestos!$B$24)*Supuestos!$B$41*(1+Supuestos!$B$43)) -> 179.93405 | D10: P = 1.4 × (operativo + comisión(P)) despejado
A11: Variante subsidiada · recuperación mensual del kit | B11: ='Costo unitario'!$B$14*(1+Supuestos!$B$25)/12 -> 911.12 | C11: ='Costo unitario'!$C$14*(1+Supuestos!$B$25)/12 -> 715.68 | D11: kit × 1.20 ÷ 12
A12: Variante subsidiada · suscripción necesaria | B12: =(1+Supuestos!$B$24)*(B11+B9+Supuestos!$B$42*(1+Supuestos!$B$43))/(1-(1+Supuestos!$B$24)*Supuestos!$B$41*(1+Supuestos!$B$43)) -> 1573.7714 | C12: =(1+Supuestos!$B$24)*(C11+C9+Supuestos!$B$42*(1+Supuestos!$B$43))/(1-(1+Supuestos!$B$24)*Supuestos!$B$41*(1+Supuestos!$B$43)) -> 1242.0863 | D12: mismo despeje con la recuperación del kit
A13: Value-based · valor mensual para el gimnasio | B13: =Supuestos!$B$57*Supuestos!$B$58 -> 1700 | C13: =Supuestos!$B$57*Supuestos!$B$58 -> 1700 | D13: alumnos retenidos × mensualidad
A14: Value-based · gasto que el dueño justifica en el primer año | B14: =B13*Supuestos!$B$59 -> 20400 | C14: =C13*Supuestos!$B$59 -> 20400 | D14: valor mensual × 12
A15: Techo del kit con la suscripción recomendada | B15: =B14-(12-Supuestos!$B$40)*Supuestos!$B$39 -> 14911 | C15: =C14-(12-Supuestos!$B$40)*Supuestos!$B$39 -> 14911 | D15: techo anual − 11 meses de suscripción
A16: Techo de la suscripción si ya tiene el hardware | B16: =B13*Supuestos!$B$60 -> 1020 | C16: =C13*Supuestos!$B$60 -> 1020 | D16: 60 % del valor mensual
A17: Precio recomendado del kit | B17: =Supuestos!$B$38 -> 13490 | C17: =Supuestos!$B$38 -> 13490 | D17: Supuestos
A18: Precio recomendado de la suscripción | B18: =Supuestos!$B$39 -> 499 | C18: =Supuestos!$B$39 -> 499 | D18: Supuestos
A19: Margen bruto del kit sobre el costo del hardware | B19: =1-'Costo unitario'!$B$14/B17 -> 0.324596 | C19: =1-'Costo unitario'!$C$14/C17 -> 0.46947368 | D19: 1 − costo ÷ precio
A20: Precio del kit sobre el piso cost-plus | B20: =B17/B4-1 -> 0.057568079 | C20: =C17/C4-1 -> 0.34637188
A21: Precio del kit bajo el techo value-based | B21: =1-B17/B15 -> 0.095298773 | C21: =1-C17/C15 -> 0.095298773
A22: Comisión por cobro de la suscripción | B22: =(Supuestos!$B$41*B18+Supuestos!$B$42)*(1+Supuestos!$B$43) -> 24.841516 | C22: =(Supuestos!$B$41*C18+Supuestos!$B$42)*(1+Supuestos!$B$43) -> 24.841516 | D22: (3.49 % × precio + $4) × 1.16
A23: Margen de la suscripción después de nube, IA, soporte, fundas y comisión | B23: =1-(B9+B22)/B18 -> 0.6603379 | C23: =1-(C9+C22)/C18 -> 0.71655032
A24: Lo que paga el gimnasio en el primer año | B24: =B17+(12-Supuestos!$B$40)*B18 -> 18979 | C24: =C17+(12-Supuestos!$B$40)*C18 -> 18979 | D24: kit + 11 meses
A25: Meses para que el gimnasio recupere lo que pagó | B25: =B24/B13 -> 11.164118 | C25: =C24/C13 -> 11.164118 | D25: primer año ÷ valor mensual
A26: Paquete de 6 pods de la semana 4 ($7,990) por pod | B26: =7990/6 -> 1331.6667 | C26: =7990/6 -> 1331.6667 | D26: comparar con el BOM

Sheet Equilibrio
A1: Paso 3 · Margen de contribución y punto de equilibrio del año 1
A3: Concepto | B3: Valor | E3: Fórmula
A4: Kit · costo directo (4 pods a 10 unidades) | B4: =Supuestos!$B$6*'Costo unitario'!$B$7 -> 6508 | E4: 4 × costo directo
A5: Kit · overhead en efectivo | B5: =B4*Supuestos!$B$22 -> 976.2 | E5: 15 % (espacio, herramientas, servicios)
A6: Kit · comisión de la pasarela | B6: =(Supuestos!$B$41*Supuestos!$B$38+Supuestos!$B$42)*(1+Supuestos!$B$43) -> 550.76916 | E6: (3.49 % × precio + $4) × 1.16
A7: Kit · envío | B7: =Supuestos!$B$44 -> 250
A8: Kit · costo variable en efectivo | B8: =SUM(B4:B7) -> 8284.9692 | E8: Las contingencias son reserva, no salida por unidad
A9: Kit · margen de contribución | B9: =Supuestos!$B$38-B8 -> 5205.0308 | E9: precio − costo variable
A10: Suscripción · costo variable mensual (IA + soporte + fundas + comisión) | B10: =IA!$B$9+Supuestos!$B$46*Supuestos!$B$15+Supuestos!$B$48*Supuestos!$B$47/3+Precio!$B$22 -> 122.74139 | E10: la nube es costo fijo
A11: Suscripción · margen de contribución mensual | B11: =Supuestos!$B$39-B10 -> 376.25861
A12: Meses de suscripción pagados por gimnasio en el año 1 (promedio) | B12: =Flujo!$B$62/Supuestos!$B$7 -> 4.5 | E12: altas de los meses 3 a 12 y primer mes gratis
A13: Suscripción · aporte del año 1 por gimnasio | B13: =B11*B12 -> 1693.1637
A14: Servicio del mes gratis (IA, soporte y fundas sin cobro) | B14: =-(IA!$B$9+Supuestos!$B$46*Supuestos!$B$15+Supuestos!$B$48*Supuestos!$B$47/3)*Supuestos!$B$40 -> -97.899873 | E14: costo del mes de prueba
A15: MARGEN DE CONTRIBUCIÓN POR GIMNASIO EN EL AÑO 1 | B15: =B9+B13+B14 -> 6800.2947 | E15: kit + suscripción − mes gratis
A17: Fijo · nube 12 meses | B17: =12*Supuestos!$B$27*Supuestos!$B$5 -> 5610
A18: Fijo · cuentas de tiendas, dominio y correo | B18: =(Supuestos!$B$52+Supuestos!$B$53)*Supuestos!$B$5+Supuestos!$B$54 -> 2918.8
A19: Fijo · herramental | B19: =Supuestos!$B$55 -> 3000
A20: Fijo · kit demo (4 pods a costo directo) | B20: =Supuestos!$B$6*'Costo unitario'!$B$7 -> 6508
A21: Fijo · marketing digital 12 meses | B21: =12*Supuestos!$B$49 -> 12000
A22: Fijo · legal y contabilidad | B22: =Supuestos!$B$51+12*Supuestos!$B$50 -> 17000
A23: COSTOS FIJOS · A (operativo) | B23: =SUM(B17:B22) -> 47036.8
A24: Fijo · persona a medio tiempo | B24: =Supuestos!$B$18*52*Supuestos!$B$15 -> 83200 | E24: 20 h/sem × 52 × $80
A25: COSTOS FIJOS · B (+ medio tiempo) | B25: =B23+B24 -> 130236.8
A26: Fijo · recuperar el desarrollo (escenario promedio) | B26: =Desarrollo!$K$19 -> 908231.3 | E26: hoja Desarrollo
A27: COSTOS FIJOS · C (+ desarrollo) | B27: =B25+B26 -> 1038468.1
A28: Fijo · solo el efectivo del desarrollo | B28: =Desarrollo!$K$22 -> 62864.865 | E28: materiales con indirectos y contingencia
A29: COSTOS FIJOS · A' (A + efectivo del desarrollo) | B29: =B23+B28 -> 109901.66
A31: Punto de equilibrio · A (gimnasios) | B31: =B23/B15 -> 6.9168767 | C31: =ROUNDUP(B31,0) -> 7 | D31: =C31*Supuestos!$B$6 -> 28 | E31: fijos ÷ margen por gimnasio
A32: Punto de equilibrio · A' (gimnasios) | B32: =B29/B15 -> 16.161309 | C32: =ROUNDUP(B32,0) -> 17 | D32: =C32*Supuestos!$B$6 -> 68
A33: Punto de equilibrio · B (gimnasios) | B33: =B25/B15 -> 19.151641 | C33: =ROUNDUP(B33,0) -> 20 | D33: =C33*Supuestos!$B$6 -> 80
A34: Punto de equilibrio · C (gimnasios) | B34: =B27/B15 -> 152.70928 | C34: =ROUNDUP(B34,0) -> 153 | D34: =C34*Supuestos!$B$6 -> 612
A35: C con el desarrollo repartido en 3 años (gimnasios por año) | B35: =(B25+B26/3)/B15 -> 63.670853 | C35: =ROUNDUP(B35,0) -> 64 | D35: =C35*Supuestos!$B$6 -> 256
A37: Cada $10,000 de certificación sube el equilibrio A en (gimnasios) | B37: =10000/B15 -> 1.4705245 | E37: homologación aún sin cotizar

Sheet Flujo
A1: Pasos 4 y 5 · Flujo de caja mensual, VPN al 15 % y extensión a 24 meses (MXN)
A2: Mes 0 = lanzamiento comercial después del lote de la semana 13. Altas: gimnasios del año 1 repartidos en los meses 3–12 y los del año 2 en los meses 13–24. Los materiales de cada kit se compran el mes anterior a la venta (en el mes 24 se compran los del mes 25). El primer mes de suscripción es gratis. Escenario A: el equipo no cobra sueldo.
A3: Concepto | B3: Mes 0 | C3: Mes 1 | D3: Mes 2 | E3: Mes 3 | F3: Mes 4 | G3: Mes 5 | H3: Mes 6 | I3: Mes 7 | J3: Mes 8 | K3: Mes 9 | L3: Mes 10 | M3: Mes 11 | N3: Mes 12 | O3: Mes 13 | P3: Mes 14 | Q3: Mes 15 | R3: Mes 16 | S3: Mes 17 | T3: Mes 18 | U3: Mes 19 | V3: Mes 20 | W3: Mes 21 | X3: Mes 22 | Y3: Mes 23 | Z3: Mes 24
A4: Mes | B4: 0 | C4: 1 | D4: 2 | E4: 3 | F4: 4 | G4: 5 | H4: 6 | I4: 7 | J4: 8 | K4: 9 | L4: 10 | M4: 11 | N4: 12 | O4: 13 | P4: 14 | Q4: 15 | R4: 16 | S4: 17 | T4: 18 | U4: 19 | V4: 20 | W4: 21 | X4: 22 | Y4: 23 | Z4: 24
A5: Año | B5: =IF(B4=0,0,IF(B4<=12,1,2)) -> 0 | C5: =IF(C4=0,0,IF(C4<=12,1,2)) -> 1 | D5: =IF(D4=0,0,IF(D4<=12,1,2)) -> 1 | E5: =IF(E4=0,0,IF(E4<=12,1,2)) -> 1 | F5: =IF(F4=0,0,IF(F4<=12,1,2)) -> 1 | G5: =IF(G4=0,0,IF(G4<=12,1,2)) -> 1 | H5: =IF(H4=0,0,IF(H4<=12,1,2)) -> 1 | I5: =IF(I4=0,0,IF(I4<=12,1,2)) -> 1 | ... Z5: =IF(Z4=0,0,IF(Z4<=12,1,2)) -> 2
A6: Kits vendidos (gimnasios nuevos) | B6: =0 -> 0 | C6: =0 -> 0 | D6: =0 -> 0 | E6: =ROUND(Supuestos!$B$7*1/10,0)-ROUND(Supuestos!$B$7*0/10,0) -> 1 | F6: =ROUND(Supuestos!$B$7*2/10,0)-ROUND(Supuestos!$B$7*1/10,0) -> 1 | G6: =ROUND(Supuestos!$B$7*3/10,0)-ROUND(Supuestos!$B$7*2/10,0) -> 1 | H6: =ROUND(Supuestos!$B$7*4/10,0)-ROUND(Supuestos!$B$7*3/10,0) -> 1 | I6: =ROUND(Supuestos!$B$7*5/10,0)-ROUND(Supuestos!$B$7*4/10,0) -> 1 | J6: =ROUND(Supuestos!$B$7*6/10,0)-ROUND(Supuestos!$B$7*5/10,0) -> 1 | K6: =ROUND(Supuestos!$B$7*7/10,0)-ROUND(Supuestos!$B$7*6/10,0) -> 1 | L6: =ROUND(Supuestos!$B$7*8/10,0)-ROUND(Supuestos!$B$7*7/10,0) -> 1 | M6: =ROUND(Supuestos!$B$7*9/10,0)-ROUND(Supuestos!$B$7*8/10,0) -> 1 | N6: =ROUND(Supuestos!$B$7*10/10,0)-ROUND(Supuestos!$B$7*9/10,0) -> 1 | O6: =ROUND(Supuestos!$B$8*1/12,0)-ROUND(Supuestos!$B$8*0/12,0) -> 2 | P6: =ROUND(Supuestos!$B$8*2/12,0)-ROUND(Supuestos!$B$8*1/12,0) -> 2 | Q6: =ROUND(Supuestos!$B$8*3/12,0)-ROUND(Supuestos!$B$8*2/12,0) -> 2 | R6: =ROUND(Supuestos!$B$8*4/12,0)-ROUND(Supuestos!$B$8*3/12,0) -> 2 | S6: =ROUND(Supuestos!$B$8*5/12,0)-ROUND(Supuestos!$B$8*4/12,0) -> 2 | T6: =ROUND(Supuestos!$B$8*6/12,0)-ROUND(Supuestos!$B$8*5/12,0) -> 3 | U6: =ROUND(Supuestos!$B$8*7/12,0)-ROUND(Supuestos!$B$8*6/12,0) -> 2 | V6: =ROUND(Supuestos!$B$8*8/12,0)-ROUND(Supuestos!$B$8*7/12,0) -> 2 | W6: =ROUND(Supuestos!$B$8*9/12,0)-ROUND(Supuestos!$B$8*8/12,0) -> 2 | X6: =ROUND(Supuestos!$B$8*10/12,0)-ROUND(Supuestos!$B$8*9/12,0) -> 2 | Y6: =ROUND(Supuestos!$B$8*11/12,0)-ROUND(Supuestos!$B$8*10/12,0) -> 2 | Z6: =ROUND(Supuestos!$B$8*12/12,0)-ROUND(Supuestos!$B$8*11/12,0) -> 2
A7: Gimnasios acumulados | B7: =B6 -> 0 | C7: =B7+C6 -> 0 | D7: =C7+D6 -> 0 | E7: =D7+E6 -> 1 | F7: =E7+F6 -> 2 | G7: =F7+G6 -> 3 | H7: =G7+H6 -> 4 | I7: =H7+I6 -> 5 | J7: =I7+J6 -> 6 | ... Z7: =Y7+Z6 -> 35
A8: Gimnasios que pagan suscripción | B8: =0 -> 0 | C8: =B7 -> 0 | D8: =C7 -> 0 | E8: =D7 -> 0 | F8: =E7 -> 1 | G8: =F7 -> 2 | H8: =G7 -> 3 | I8: =H7 -> 4 | J8: =I7 -> 5 | ... Z8: =Y7 -> 33
A10: Entrada: venta de kits | B10: =B6*Supuestos!$B$38 -> 0 | C10: =C6*Supuestos!$B$38 -> 0 | D10: =D6*Supuestos!$B$38 -> 0 | E10: =E6*Supuestos!$B$38 -> 13490 | F10: =F6*Supuestos!$B$38 -> 13490 | G10: =G6*Supuestos!$B$38 -> 13490 | H10: =H6*Supuestos!$B$38 -> 13490 | I10: =I6*Supuestos!$B$38 -> 13490 | ... Z10: =Z6*Supuestos!$B$38 -> 26980
A11: Entrada: suscripciones | B11: =B8*Supuestos!$B$39 -> 0 | C11: =C8*Supuestos!$B$39 -> 0 | D11: =D8*Supuestos!$B$39 -> 0 | E11: =E8*Supuestos!$B$39 -> 0 | F11: =F8*Supuestos!$B$39 -> 499 | G11: =G8*Supuestos!$B$39 -> 998 | H11: =H8*Supuestos!$B$39 -> 1497 | I11: =I8*Supuestos!$B$39 -> 1996 | ... Z11: =Z8*Supuestos!$B$39 -> 16467
A12: Total de entradas | B12: =B10+B11 -> 0 | C12: =C10+C11 -> 0 | D12: =D10+D11 -> 0 | E12: =E10+E11 -> 13490 | F12: =F10+F11 -> 13989 | G12: =G10+G11 -> 14488 | H12: =H10+H11 -> 14987 | I12: =I10+I11 -> 15486 | ... Z12: =Z10+Z11 -> 43447
A14: Salida: materiales, ensamble y overhead (mes anterior a la venta) | B14: =C6*Supuestos!$B$6*IF(C5<=1,'Costo unitario'!$B$7,'Costo unitario'!$C$7)*(1+Supuestos!$B$22) -> 0 | C14: =D6*Supuestos!$B$6*IF(D5<=1,'Costo unitario'!$B$7,'Costo unitario'!$C$7)*(1+Supuestos!$B$22) -> 0 | D14: =E6*Supuestos!$B$6*IF(E5<=1,'Costo unitario'!$B$7,'Costo unitario'!$C$7)*(1+Supuestos!$B$22) -> 7484.2 | E14: =F6*Supuestos!$B$6*IF(F5<=1,'Costo unitario'!$B$7,'Costo unitario'!$C$7)*(1+Supuestos!$B$22) -> 7484.2 | F14: =G6*Supuestos!$B$6*IF(G5<=1,'Costo unitario'!$B$7,'Costo unitario'!$C$7)*(1+Supuestos!$B$22) -> 7484.2 | G14: =H6*Supuestos!$B$6*IF(H5<=1,'Costo unitario'!$B$7,'Costo unitario'!$C$7)*(1+Supuestos!$B$22) -> 7484.2 | H14: =I6*Supuestos!$B$6*IF(I5<=1,'Costo unitario'!$B$7,'Costo unitario'!$C$7)*(1+Supuestos!$B$22) -> 7484.2 | I14: =J6*Supuestos!$B$6*IF(J5<=1,'Costo unitario'!$B$7,'Costo unitario'!$C$7)*(1+Supuestos!$B$22) -> 7484.2 | ... Y14: =Z6*Supuestos!$B$6*IF(Z5<=1,'Costo unitario'!$B$7,'Costo unitario'!$C$7)*(1+Supuestos!$B$22) -> 11757.6 | Z14: =ROUND(Supuestos!$B$8/12,0)*Supuestos!$B$6*'Costo unitario'!$C$7*(1+Supuestos!$B$22) -> 11757.6
A15: Salida: comisión de la pasarela en kits | B15: =B6*(Supuestos!$B$41*Supuestos!$B$38+Supuestos!$B$42)*(1+Supuestos!$B$43) -> 0 | C15: =C6*(Supuestos!$B$41*Supuestos!$B$38+Supuestos!$B$42)*(1+Supuestos!$B$43) -> 0 | D15: =D6*(Supuestos!$B$41*Supuestos!$B$38+Supuestos!$B$42)*(1+Supuestos!$B$43) -> 0 | E15: =E6*(Supuestos!$B$41*Supuestos!$B$38+Supuestos!$B$42)*(1+Supuestos!$B$43) -> 550.76916 | F15: =F6*(Supuestos!$B$41*Supuestos!$B$38+Supuestos!$B$42)*(1+Supuestos!$B$43) -> 550.76916 | G15: =G6*(Supuestos!$B$41*Supuestos!$B$38+Supuestos!$B$42)*(1+Supuestos!$B$43) -> 550.76916 | H15: =H6*(Supuestos!$B$41*Supuestos!$B$38+Supuestos!$B$42)*(1+Supuestos!$B$43) -> 550.76916 | I15: =I6*(Supuestos!$B$41*Supuestos!$B$38+Supuestos!$B$42)*(1+Supuestos!$B$43) -> 550.76916 | ... Z15: =Z6*(Supuestos!$B$41*Supuestos!$B$38+Supuestos!$B$42)*(1+Supuestos!$B$43) -> 1101.5383
A16: Salida: envío de kits | B16: =B6*Supuestos!$B$44 -> 0 | C16: =C6*Supuestos!$B$44 -> 0 | D16: =D6*Supuestos!$B$44 -> 0 | E16: =E6*Supuestos!$B$44 -> 250 | F16: =F6*Supuestos!$B$44 -> 250 | G16: =G6*Supuestos!$B$44 -> 250 | H16: =H6*Supuestos!$B$44 -> 250 | I16: =I6*Supuestos!$B$44 -> 250 | ... Z16: =Z6*Supuestos!$B$44 -> 500
A17: Salida: comisión de la pasarela en suscripciones | B17: =B8*(Supuestos!$B$41*Supuestos!$B$39+Supuestos!$B$42)*(1+Supuestos!$B$43) -> 0 | C17: =C8*(Supuestos!$B$41*Supuestos!$B$39+Supuestos!$B$42)*(1+Supuestos!$B$43) -> 0 | D17: =D8*(Supuestos!$B$41*Supuestos!$B$39+Supuestos!$B$42)*(1+Supuestos!$B$43) -> 0 | E17: =E8*(Supuestos!$B$41*Supuestos!$B$39+Supuestos!$B$42)*(1+Supuestos!$B$43) -> 0 | F17: =F8*(Supuestos!$B$41*Supuestos!$B$39+Supuestos!$B$42)*(1+Supuestos!$B$43) -> 24.841516 | G17: =G8*(Supuestos!$B$41*Supuestos!$B$39+Supuestos!$B$42)*(1+Supuestos!$B$43) -> 49.683032 | H17: =H8*(Supuestos!$B$41*Supuestos!$B$39+Supuestos!$B$42)*(1+Supuestos!$B$43) -> 74.524548 | I17: =I8*(Supuestos!$B$41*Supuestos!$B$39+Supuestos!$B$42)*(1+Supuestos!$B$43) -> 99.366064 | ... Z17: =Z8*(Supuestos!$B$41*Supuestos!$B$39+Supuestos!$B$42)*(1+Supuestos!$B$43) -> 819.77003
A18: Salida: IA, soporte y fundas por gimnasio activo | B18: =B7*(IA!$B$9+Supuestos!$B$46*Supuestos!$B$15+Supuestos!$B$48*Supuestos!$B$47/3) -> 0 | C18: =C7*(IA!$B$9+Supuestos!$B$46*Supuestos!$B$15+Supuestos!$B$48*Supuestos!$B$47/3) -> 0 | D18: =D7*(IA!$B$9+Supuestos!$B$46*Supuestos!$B$15+Supuestos!$B$48*Supuestos!$B$47/3) -> 0 | E18: =E7*(IA!$B$9+Supuestos!$B$46*Supuestos!$B$15+Supuestos!$B$48*Supuestos!$B$47/3) -> 97.899873 | F18: =F7*(IA!$B$9+Supuestos!$B$46*Supuestos!$B$15+Supuestos!$B$48*Supuestos!$B$47/3) -> 195.79975 | G18: =G7*(IA!$B$9+Supuestos!$B$46*Supuestos!$B$15+Supuestos!$B$48*Supuestos!$B$47/3) -> 293.69962 | H18: =H7*(IA!$B$9+Supuestos!$B$46*Supuestos!$B$15+Supuestos!$B$48*Supuestos!$B$47/3) -> 391.59949 | I18: =I7*(IA!$B$9+Supuestos!$B$46*Supuestos!$B$15+Supuestos!$B$48*Supuestos!$B$47/3) -> 489.49937 | ... Z18: =Z7*(IA!$B$9+Supuestos!$B$46*Supuestos!$B$15+Supuestos!$B$48*Supuestos!$B$47/3) -> 3426.4956
A19: Salida: nube (Supabase Pro) | B19: =0 -> 0 | C19: =Supuestos!$B$27*Supuestos!$B$5 -> 467.5 | D19: =Supuestos!$B$27*Supuestos!$B$5 -> 467.5 | E19: =Supuestos!$B$27*Supuestos!$B$5 -> 467.5 | F19: =Supuestos!$B$27*Supuestos!$B$5 -> 467.5 | G19: =Supuestos!$B$27*Supuestos!$B$5 -> 467.5 | H19: =Supuestos!$B$27*Supuestos!$B$5 -> 467.5 | I19: =Supuestos!$B$27*Supuestos!$B$5 -> 467.5 | J19: =Supuestos!$B$27*Supuestos!$B$5 -> 467.5 | ... Z19: =Supuestos!$B$27*Supuestos!$B$5 -> 467.5
A20: Salida: marketing digital | B20: =0 -> 0 | C20: =Supuestos!$B$49 -> 1000 | D20: =Supuestos!$B$49 -> 1000 | E20: =Supuestos!$B$49 -> 1000 | F20: =Supuestos!$B$49 -> 1000 | G20: =Supuestos!$B$49 -> 1000 | H20: =Supuestos!$B$49 -> 1000 | I20: =Supuestos!$B$49 -> 1000 | J20: =Supuestos!$B$49 -> 1000 | ... Z20: =Supuestos!$B$49 -> 1000
A21: Salida: contabilidad | B21: =0 -> 0 | C21: =Supuestos!$B$50 -> 1000 | D21: =Supuestos!$B$50 -> 1000 | E21: =Supuestos!$B$50 -> 1000 | F21: =Supuestos!$B$50 -> 1000 | G21: =Supuestos!$B$50 -> 1000 | H21: =Supuestos!$B$50 -> 1000 | I21: =Supuestos!$B$50 -> 1000 | J21: =Supuestos!$B$50 -> 1000 | ... Z21: =Supuestos!$B$50 -> 1000
A22: Salida: cuentas de tiendas, dominio y correo | B22: =(Supuestos!$B$52+Supuestos!$B$53)*Supuestos!$B$5+Supuestos!$B$54 -> 2918.8 | C22: =0 -> 0 | D22: =0 -> 0 | E22: =0 -> 0 | F22: =0 -> 0 | G22: =0 -> 0 | H22: =0 -> 0 | I22: =0 -> 0 | J22: =0 -> 0 | ... M22: =0 -> 0 | N22: =Supuestos!$B$52*Supuestos!$B$5+Supuestos!$B$54 -> 2451.3 | O22: =0 -> 0 | P22: =0 -> 0 | Q22: =0 -> 0 | R22: =0 -> 0 | S22: =0 -> 0 | T22: =0 -> 0 | U22: =0 -> 0 | V22: =0 -> 0 | ... Z22: =0 -> 0
A23: Inversión inicial (desarrollo en efectivo, herramental, kit demo, legal) | B23: =Desarrollo!$K$22+Supuestos!$B$55+Supuestos!$B$6*'Costo unitario'!$B$7+Supuestos!$B$51 -> 77372.865 | C23: =0 -> 0 | D23: =0 -> 0 | E23: =0 -> 0 | F23: =0 -> 0 | G23: =0 -> 0 | H23: =0 -> 0 | I23: =0 -> 0 | J23: =0 -> 0 | ... Z23: =0 -> 0
A24: Total de salidas | B24: =SUM(B14:B23) -> 80291.665 | C24: =SUM(C14:C23) -> 2467.5 | D24: =SUM(D14:D23) -> 9951.7 | E24: =SUM(E14:E23) -> 10850.369 | F24: =SUM(F14:F23) -> 10973.11 | G24: =SUM(G14:G23) -> 11095.852 | H24: =SUM(H14:H23) -> 11218.593 | I24: =SUM(I14:I23) -> 11341.335 | ... Z24: =SUM(Z14:Z23) -> 20072.904
A26: FLUJO NETO · A (sin sueldos) | B26: =B12-B24 -> -80291.665 | C26: =C12-C24 -> -2467.5 | D26: =D12-D24 -> -9951.7 | E26: =E12-E24 -> 2639.631 | F26: =F12-F24 -> 3015.8896 | G26: =G12-G24 -> 3392.1482 | H26: =H12-H24 -> 3768.4068 | I26: =I12-I24 -> 4144.6654 | ... Z26: =Z12-Z24 -> 23374.096
A27: Flujo acumulado · A | B27: =B26 -> -80291.665 | C27: =B27+C26 -> -82759.165 | D27: =C27+D26 -> -92710.865 | E27: =D27+E26 -> -90071.234 | F27: =E27+F26 -> -87055.344 | G27: =F27+G26 -> -83663.196 | H27: =G27+H26 -> -79894.789 | I27: =H27+I26 -> -75750.124 | J27: =I27+J26 -> -71229.2 | ... Z27: =Y27+Z26 -> 179170.38
A28: Factor de descuento (15 % anual → mensual) | B28: =1/(1+((1+Supuestos!$B$61)^(1/12)-1))^B4 -> 1 | C28: =1/(1+((1+Supuestos!$B$61)^(1/12)-1))^C4 -> 0.98842073 | D28: =1/(1+((1+Supuestos!$B$61)^(1/12)-1))^D4 -> 0.97697555 | E28: =1/(1+((1+Supuestos!$B$61)^(1/12)-1))^E4 -> 0.96566289 | F28: =1/(1+((1+Supuestos!$B$61)^(1/12)-1))^F4 -> 0.95448122 | G28: =1/(1+((1+Supuestos!$B$61)^(1/12)-1))^G4 -> 0.94342902 | H28: =1/(1+((1+Supuestos!$B$61)^(1/12)-1))^H4 -> 0.93250481 | I28: =1/(1+((1+Supuestos!$B$61)^(1/12)-1))^I4 -> 0.92170709 | ... Z28: =1/(1+((1+Supuestos!$B$61)^(1/12)-1))^Z4 -> 0.75614367
A29: Valor presente · A | B29: =B26*B28 -> -80291.665 | C29: =C26*C28 -> -2438.9282 | D29: =D26*D28 -> -9722.5675 | E29: =E26*E28 -> 2548.9937 | F29: =F26*F28 -> 2878.61 | G29: =G26*G28 -> 3200.2511 | H29: =H26*H28 -> 3514.0575 | I29: =I26*I28 -> 3820.1675 | ... Z29: =Z26*Z28 -> 17674.175
A31: Escenario B: persona a medio tiempo | B31: =0 -> 0 | C31: =Supuestos!$B$18*52/12*Supuestos!$B$15 -> 6933.3333 | D31: =Supuestos!$B$18*52/12*Supuestos!$B$15 -> 6933.3333 | E31: =Supuestos!$B$18*52/12*Supuestos!$B$15 -> 6933.3333 | F31: =Supuestos!$B$18*52/12*Supuestos!$B$15 -> 6933.3333 | G31: =Supuestos!$B$18*52/12*Supuestos!$B$15 -> 6933.3333 | H31: =Supuestos!$B$18*52/12*Supuestos!$B$15 -> 6933.3333 | I31: =Supuestos!$B$18*52/12*Supuestos!$B$15 -> 6933.3333 | J31: =Supuestos!$B$18*52/12*Supuestos!$B$15 -> 6933.3333 | ... Z31: =Supuestos!$B$18*52/12*Supuestos!$B$15 -> 6933.3333
A32: FLUJO NETO · B (+ medio tiempo) | B32: =B26-B31 -> -80291.665 | C32: =C26-C31 -> -9400.8333 | D32: =D26-D31 -> -16885.033 | E32: =E26-E31 -> -4293.7024 | F32: =F26-F31 -> -3917.4438 | G32: =G26-G31 -> -3541.1851 | H32: =H26-H31 -> -3164.9265 | I32: =I26-I31 -> -2788.6679 | ... Z32: =Z26-Z31 -> 16440.763
A33: Flujo acumulado · B | B33: =B32 -> -80291.665 | C33: =B33+C32 -> -89692.498 | D33: =C33+D32 -> -106577.53 | E33: =D33+E32 -> -110871.23 | F33: =E33+F32 -> -114788.68 | G33: =F33+G32 -> -118329.86 | H33: =G33+H32 -> -121494.79 | I33: =H33+I32 -> -124283.46 | J33: =I33+J32 -> -126695.87 | ... Z33: =Y33+Z32 -> 12770.378
A34: Valor presente · B | B34: =B32*B28 -> -80291.665 | C34: =C32*C28 -> -9291.9786 | D34: =D32*D28 -> -16496.265 | E34: =E32*E28 -> -4146.269 | F34: =F32*F28 -> -3739.1265 | G34: =G32*G28 -> -3340.8568 | H34: =H32*H28 -> -2951.3092 | I34: =I32*I28 -> -2570.335 | ... Z34: =Z32*Z28 -> 12431.579
A36: Escenario C: mano de obra del desarrollo a $195/h (mes 0) | B36: =Desarrollo!$K$23 -> 845366.44 | C36: =0 -> 0 | D36: =0 -> 0 | E36: =0 -> 0 | F36: =0 -> 0 | G36: =0 -> 0 | H36: =0 -> 0 | I36: =0 -> 0 | J36: =0 -> 0 | ... Z36: =0 -> 0
A37: FLUJO NETO · C (B + desarrollo completo) | B37: =B32-B36 -> -925658.1 | C37: =C32-C36 -> -9400.8333 | D37: =D32-D36 -> -16885.033 | E37: =E32-E36 -> -4293.7024 | F37: =F32-F36 -> -3917.4438 | G37: =G32-G36 -> -3541.1851 | H37: =H32-H36 -> -3164.9265 | I37: =I32-I36 -> -2788.6679 | ... Z37: =Z32-Z36 -> 16440.763
A38: Flujo acumulado · C | B38: =B37 -> -925658.1 | C38: =B38+C37 -> -935058.94 | D38: =C38+D37 -> -951943.97 | E38: =D38+E37 -> -956237.67 | F38: =E38+F37 -> -960155.12 | G38: =F38+G37 -> -963696.3 | H38: =G38+H37 -> -966861.23 | I38: =H38+I37 -> -969649.89 | J38: =I38+J37 -> -972062.3 | ... Z38: =Y38+Z37 -> -832596.06
A39: Valor presente · C | B39: =B37*B28 -> -925658.1 | C39: =C37*C28 -> -9291.9786 | D39: =D37*D28 -> -16496.265 | E39: =E37*E28 -> -4146.269 | F39: =F37*F28 -> -3739.1265 | G39: =G37*G28 -> -3340.8568 | H39: =H37*H28 -> -2951.3092 | I39: =I37*I28 -> -2570.335 | ... Z39: =Z37*Z28 -> 12431.579
A41: Ayuda: mes con flujo mensual A positivo | B41: =99 -> 99 | C41: =IF(C26>0,C4,99) -> 99 | D41: =IF(D26>0,D4,99) -> 99 | E41: =IF(E26>0,E4,99) -> 3 | F41: =IF(F26>0,F4,99) -> 4 | G41: =IF(G26>0,G4,99) -> 5 | H41: =IF(H26>0,H4,99) -> 6 | I41: =IF(I26>0,I4,99) -> 7 | J41: =IF(J26>0,J4,99) -> 8 | ... Z41: =IF(Z26>0,Z4,99) -> 24
A42: Ayuda: mes con acumulado A ≥ 0 | B42: =99 -> 99 | C42: =IF(C27>=0,C4,99) -> 99 | D42: =IF(D27>=0,D4,99) -> 99 | E42: =IF(E27>=0,E4,99) -> 99 | F42: =IF(F27>=0,F4,99) -> 99 | G42: =IF(G27>=0,G4,99) -> 99 | H42: =IF(H27>=0,H4,99) -> 99 | I42: =IF(I27>=0,I4,99) -> 99 | J42: =IF(J27>=0,J4,99) -> 99 | ... Z42: =IF(Z27>=0,Z4,99) -> 24
A44: RESULTADOS
A45: Tasa mensual equivalente | B45: =((1+Supuestos!$B$61)^(1/12)-1) -> 0.011714917
A46: VPN a 12 meses · A | B46: =SUM(B29:N29) -> -58906.119
A47: VPN a 12 meses · B | B47: =SUM(B34:N34) -> -136102.38
...

Sheet Desarrollo
A1: Costo de desarrollo · ciclos de aprendizaje por subsistema
A2: Costo por ciclo = (horas × costo por hora de ingeniería + materiales) × (1 + overhead) × (1 + contingencia). Horas, materiales y número de ciclos son [Estimado].
A3: Subsistema | B3: h/ciclo | C3: Materiales/ciclo | D3: Qué incluyen los materiales | E3: Contingencia | F3: Costo por ciclo | G3: Mín | H3: Prom | I3: Máx | J3: Total mínimo | K3: Total promedio | L3: Total máximo | M3: % del promedio
A4: S1. Estructura del pod | B4: 60 | C4: 1040 | D4: 2 carcasas Ø 160, 2 platos Ø 118, 2 pads Ø 120, tornillería e insertos | E4: 0.3 | F4: =(B4*Supuestos!$B$14+C4)*(1+Supuestos!$B$22)*(1+E4) -> 19046.3 | G4: 3 | H4: 5 | I4: 7 | J4: =F4*G4 -> 57138.9 | K4: =F4*H4 -> 95231.5 | L4: =F4*I4 -> 133324.1 | M4: =K4/$K$19 -> 0.1048538
A5: S2. Montaje y fijación | B5: 20 | C5: 320 | D5: Placas Ø 120, bases y adaptador de costal impresos, taquetes | E5: 0.25 | F5: =(B5*Supuestos!$B$14+C5)*(1+Supuestos!$B$22)*(1+E5) -> 6066.25 | G5: 2 | H5: 3 | I5: 4 | J5: =F5*G5 -> 12132.5 | K5: =F5*H5 -> 18198.75 | L5: =F5*I5 -> 24265 | M5: =K5/$K$19 -> 0.020037572
A6: S3. Sensado de impacto | B6: 50 | C6: 1500 | D6: 2 juegos de sensores (ADXL375, 4 celdas, ADS1220) + pesas y péndulo | E6: 0.3 | F6: =(B6*Supuestos!$B$14+C6)*(1+Supuestos!$B$22)*(1+E6) -> 16818.75 | G6: 3 | H6: 4 | I6: 6 | J6: =F6*G6 -> 50456.25 | K6: =F6*H6 -> 67275 | L6: =F6*I6 -> 100912.5 | M6: =K6/$K$19 -> 0.074072541
A7: S4. Interfaz luminosa | B7: 20 | C7: 270 | D7: Tiras de 144 LED/m (18 LED) y difusores | E7: 0.25 | F7: =(B7*Supuestos!$B$14+C7)*(1+Supuestos!$B$22)*(1+E7) -> 5994.375 | G7: 2 | H7: 3 | I7: 4 | J7: =F7*G7 -> 11988.75 | K7: =F7*H7 -> 17983.125 | L7: =F7*I7 -> 23977.5 | M7: =K7/$K$19 -> 0.01980016
A8: S5. Electrónica de control | B8: 60 | C8: 1700 | D8: 5 PCB con envío + componentes para 2 placas | E8: 0.3 | F8: =(B8*Supuestos!$B$14+C8)*(1+Supuestos!$B$22)*(1+E8) -> 20033 | G8: 3 | H8: 4 | I8: 5 | J8: =F8*G8 -> 60099 | K8: =F8*H8 -> 80132 | L8: =F8*I8 -> 100165 | M8: =K8/$K$19 -> 0.088228626
A9: S6. Batería y energía | B9: 25 | C9: 500 | D9: 2 celdas 18650 + protecciones | E9: 0.3 | F9: =(B9*Supuestos!$B$14+C9)*(1+Supuestos!$B$22)*(1+E9) -> 8035.625 | G9: 2 | H9: 3 | I9: 4 | J9: =F9*G9 -> 16071.25 | K9: =F9*H9 -> 24106.875 | L9: =F9*I9 -> 32142.5 | M9: =K9/$K$19 -> 0.02654266
A10: S7. Cargador y apilamiento | B10: 40 | C10: 900 | D10: 2 pares de pogo, imanes, Hall, cargador multipuerto, base | E10: 0.3 | F10: =(B10*Supuestos!$B$14+C10)*(1+Supuestos!$B$22)*(1+E10) -> 13006.5 | G10: 3 | H10: 4 | I10: 6 | J10: =F10*G10 -> 39019.5 | K10: =F10*H10 -> 52026 | L10: =F10*I10 -> 78039 | M10: =K10/$K$19 -> 0.057282765
A11: S8. Firmware del pod | B11: 80 | C11: 300 | D11: DevKits ESP32 y consumibles | E11: 0.3 | F11: =(B11*Supuestos!$B$14+C11)*(1+Supuestos!$B$22)*(1+E11) -> 23770.5 | G11: 4 | H11: 6 | I11: 8 | J11: =F11*G11 -> 95082 | K11: =F11*H11 -> 142623 | L11: =F11*I11 -> 190164 | M11: =K11/$K$19 -> 0.15703379
A12: S9. Comunicación | B12: 50 | C12: 450 | D12: 3 DevKits ESP32 | E12: 0.3 | F12: =(B12*Supuestos!$B$14+C12)*(1+Supuestos!$B$22)*(1+E12) -> 15249 | G12: 3 | H12: 4 | I12: 6 | J12: =F12*G12 -> 45747 | K12: =F12*H12 -> 60996 | L12: =F12*I12 -> 91494 | M12: =K12/$K$19 -> 0.067159103
A13: S10. App móvil | B13: 100 | C13: 200 | D13: Incentivos para pruebas con usuarios | E13: 0.25 | F13: =(B13*Supuestos!$B$14+C13)*(1+Supuestos!$B$22)*(1+E13) -> 28318.75 | G13: 4 | H13: 6 | I13: 8 | J13: =F13*G13 -> 113275 | K13: =F13*H13 -> 169912.5 | L13: =F13*I13 -> 226550 | M13: =K13/$K$19 -> 0.18708065
A14: S11. Backend y nube | B14: 30 | C14: 468 | D14: 1 mes de Supabase Pro | E14: 0.25 | F14: =(B14*Supuestos!$B$14+C14)*(1+Supuestos!$B$22)*(1+E14) -> 9082.125 | G14: 2 | H14: 3 | I14: 5 | J14: =F14*G14 -> 18164.25 | K14: =F14*H14 -> 27246.375 | L14: =F14*I14 -> 45410.625 | M14: =K14/$K$19 -> 0.029999379
A15: S12. Análisis e IA | B15: 30 | C15: 100 | D15: Tokens de prueba | E15: 0.25 | F15: =(B15*Supuestos!$B$14+C15)*(1+Supuestos!$B$22)*(1+E15) -> 8553.125 | G15: 3 | H15: 4 | I15: 6 | J15: =F15*G15 -> 25659.375 | K15: =F15*H15 -> 34212.5 | L15: =F15*I15 -> 51318.75 | M15: =K15/$K$19 -> 0.037669369
... A17: S14. Empaque, manual e instalación | B17: 20 | C17: 400 | D17: Muestras de caja e impresión del manual | E17: 0.25 | F17: =(B17*Supuestos!$B$14+C17)*(1+Supuestos!$B$22)*(1+E17) -> 6181.25 | G17: 2 | H17: 2 | I17: 3 | J17: =F17*G17 -> 12362.5 | K17: =F17*H17 -> 12362.5 | L17: =F17*I17 -> 18543.75 | M17: =K17/$K$19 -> 0.013611621
A18: S15. Integración y validación del kit | B18: 80 | C18: =ROUND(BOM!$F$19*4*0.5,0)+300 -> 3234 | D18: 4 pods (50 % de piezas reutilizadas) + traslado al gimnasio | E18: 0.3 | F18: =(B18*Supuestos!$B$14+C18)*(1+Supuestos!$B$22)*(1+E18) -> 28156.83 | G18: 2 | H18: 3 | I18: 5 | J18: =F18*G18 -> 56313.66 | K18: =F18*H18 -> 84470.49 | L18: =F18*I18 -> 140784.15 | M18: =K18/$K$19 -> 0.093005482
A19: Total | J19: =SUM(J4:J18) -> 627813.06 | K19: =SUM(K4:K18) -> 908231.3 | L19: =SUM(L4:L18) -> 1285697.1
A20: Horas de ingeniería | J20: =SUMPRODUCT(B4:B18,G4:G18) -> 2030 | K20: =SUMPRODUCT(B4:B18,H4:H18) -> 2940 | L20: =SUMPRODUCT(B4:B18,I4:I18) -> 4150
A21: Personas-mes | J21: =J20/(Supuestos!$B$12*52/12) -> 11.624356 | K21: =K20/(Supuestos!$B$12*52/12) -> 16.835274 | L21: =L20/(Supuestos!$B$12*52/12) -> 23.764077
A22: Parte en efectivo (materiales con indirectos y contingencia) | J22: =SUMPRODUCT(C4:C18*(1+Supuestos!$B$22)*(1+E4:E18),G4:G18) -> 44090.31 | K22: =SUMPRODUCT(C4:C18*(1+Supuestos!$B$22)*(1+E4:E18),H4:H18) -> 62864.865 | L22: =SUMPRODUCT(C4:C18*(1+Supuestos!$B$22)*(1+E4:E18),I4:I18) -> 92126.5
A23: Parte de mano de obra (costo de oportunidad) | J23: =J19-J22 -> 583722.75 | K23: =K19-K22 -> 845366.44 | L23: =L19-L22 -> 1193570.6
A24: Software (S8–S13) como % del promedio | K24: =SUM(K11:K16)/K19 -> 0.50256478
A25: Hardware (S1–S7) como % del promedio | K25: =SUM(K4:K10)/K19 -> 0.39081812
A26: Método anterior (5 ciclos × 120 h) con la tarifa nueva | K26: =(120*Supuestos!$B$14+300+5000)*(1+Supuestos!$B$22)*1.3*5 -> 214532.5

Sheet D-F-S
A1: Inventario de costos · plantilla de la clase con clasificación D/F/S (año 1, 10 gimnasios = 40 pods)
A3: Costo | B3: D/F/S | C3: Costo estimado | D3: Unidad de medida | E3: Unidades que produce | F3: Costo unitario por pod | G3: Por qué
A4: CREAR la oferta
A5: 4 celdas de carga + ADS1220 + plato de aluminio | B5: D | C5: =BOM!$F$6+BOM!$F$7+BOM!$F$13 -> 235 | D5: por pod | E5: 1 | F5: =IFERROR(C5/E5,0) -> 235 | G5: Miden fuerza en N igual en pared, piso o costal; ningún competidor de pods lo hace
A6: Arco de 18 LED + difusor + pad de vinipiel | B6: D | C6: =BOM!$F$9+BOM!$F$16 -> 115 | D6: por pod | E6: 1 | F6: =IFERROR(C6/E6,0) -> 115 | G6: Experiencia del golpe y señal "golpea aquí"
A7: ADXL375 (acelerómetro ±200 g) | B7: F | C7: =BOM!$F$5 -> 425 | D7: por pod | E7: 1 | F7: =IFERROR(C7/E7,0) -> 425 | G7: La pieza más cara; con las celdas, la fuerza ya está cubierta: H3LIS331DL o solo en versión Pro
A8: ESP32, celda 18650, carga y pasivos | B8: F | C8: =BOM!$F$4+BOM!$F$8+BOM!$F$10 -> 281 | D8: por pod | E8: 1 | F8: =IFERROR(C8/E8,0) -> 281 | G8: Intercambiables por equivalentes
A9: Conector pogo magnético | B9: F | C9: =BOM!$F$11 -> 80 | D9: por pod | E9: 1 | F9: =IFERROR(C9/E9,0) -> 80 | G9: Se puede diferir: USB-C basta en la primera versión
A10: PCB + ensamble de 2 CI en JLCPCB | B10: S | C10: =BOM!$F$12 -> 91 | D10: por pod | E10: 1 | F10: =IFERROR(C10/E10,0) -> 91 | G10: Precio de mercado sin negociación
A11: Carcasa, tornillería, burlete y placa de pared | B11: F | C11: =BOM!$F$14+BOM!$F$15+BOM!$F$17+BOM!$F$18 -> 240 | D11: por pod | E11: 1 | F11: =IFERROR(C11/E11,0) -> 240 | G11: FDM ahora; molde solo con volumen
A12: Ensamble, calibración y prueba | B12: F | C12: =Supuestos!$B$16*Supuestos!$B$15 -> 120 | D12: por pod | E12: 1 | F12: =IFERROR(C12/E12,0) -> 120 | G12: Baja a ≈ 1 h con plantillas
A13: Nube (Supabase Pro), 12 meses | B13: S | C13: =12*Supuestos!$B$27*Supuestos!$B$5 -> 5610 | D13: por año | E13: =(Supuestos!$B$7*Supuestos!$B$6) -> 40 | F13: =IFERROR(C13/E13,0) -> 140.25 | G13: Precio de lista; el plan gratuito pausa proyectos
A14: IA (Claude Haiku 5.5), 12 meses | B14: D | C14: =12*IA!$B$9 -> 54.79848 | D14: por gimnasio al año | E14: =Supuestos!$B$6 -> 4 | F14: =IFERROR(C14/E14,0) -> 13.69962 | G14: Recomendaciones en lenguaje de entrenador
A15: Cuentas de Apple y Google, dominio | B15: S | C15: =(Supuestos!$B$52+Supuestos!$B$53)*Supuestos!$B$5+Supuestos!$B$54 -> 2918.8 | D15: por año | E15: =(Supuestos!$B$7*Supuestos!$B$6) -> 40 | F15: =IFERROR(C15/E15,0) -> 72.97 | G15: Tarifas fijas de las tiendas
A16: DISTRIBUIR la oferta
A17: Empaque del kit (caja + espuma) | B17: F | C17: =Supuestos!$B$20 -> 160 | D17: por kit | E17: =Supuestos!$B$6 -> 4 | F17: =IFERROR(C17/E17,0) -> 40 | G17: Se puede simplificar
A18: Envío nacional | B18: S | C18: =Supuestos!$B$44 -> 250 | D18: por kit | E18: =Supuestos!$B$6 -> 4 | F18: =IFERROR(C18/E18,0) -> 62.5 | G18: Tarifa de paquetería
A19: Comisión de pasarela en el kit | B19: S | C19: =Equilibrio!$B$6 -> 550.76916 | D19: por kit | E19: =Supuestos!$B$6 -> 4 | F19: =IFERROR(C19/E19,0) -> 137.69229 | G19: 3.49 % + $4 + IVA (Mercado Pago); se cobra fuera de las tiendas de apps
A20: Soporte técnico, 12 meses | B20: F | C20: =12*Supuestos!$B$46*Supuestos!$B$15 -> 960 | D20: por gimnasio al año | E20: =Supuestos!$B$6 -> 4 | F20: =IFERROR(C20/E20,0) -> 240 | G20: Baja con buena guía de instalación
A21: Fundas de repuesto, 12 meses | B21: F | C21: =4*Supuestos!$B$48*Supuestos!$B$47 -> 160 | D21: por gimnasio al año | E21: =Supuestos!$B$6 -> 4 | F21: =IFERROR(C21/E21,0) -> 40 | G21: 4 fundas cada 3 meses
A22: Actualizaciones de firmware OTA | B22: F | C22: =0 -> 0 | D22: incluido en S8 y S11 | E22: 1 | F22: =IFERROR(C22/E22,0) -> 0 | G22: Partición OTA de ESP-IDF + almacenamiento de Supabase; sin costo extra
A23: Kit demo y marketing digital | B23: F | C23: =Equilibrio!$B$20+Equilibrio!$B$21 -> 18508 | D23: por año | E23: =(Supuestos!$B$7*Supuestos!$B$6) -> 40 | F23: =IFERROR(C23/E23,0) -> 462.7 | G23: Kit al costo directo + $1,000/mes
A24: Aviso de privacidad, contrato SaaS, contador | B24: S | C24: =Equilibrio!$B$22 -> 17000 | D24: por año | E24: =(Supuestos!$B$7*Supuestos!$B$6) -> 40 | F24: =IFERROR(C24/E24,0) -> 425 | G24: Obligatorio con la ley de datos de 2025
A25: Homologación de radio y NOM | B25: S | C25: =0 -> 0 | D25: por modelo | E25: 1 | F25: =IFERROR(C25/E25,0) -> 0 | G25: Sin cotizar: se agrega cuando un organismo de certificación dé precio [Verificar]
A26: Costo unitario total por pod (año 1) | F26: =SUM(F5:F25) -> 3221.8119
A27: · de diferenciación (D) | F27: =SUMIF(B5:B25,"D",F5:F25) -> 363.69962
A28: · flexibles (F) | F28: =SUMIF(B5:B25,"F",F5:F25) -> 1928.7
A29: · establecidos (S) | F29: =SUMIF(B5:B25,"S",F5:F25) -> 929.41229
A30: Sin overhead ni contingencias: es el costo en efectivo que se mueve por pod.

Sheet Ejercicios
A1: Ejercicios 1 a 9 de la semana 7 · resolución con fórmulas
A4: Ejercicio 1 · VF de USD 45,000 al 7.5 % anual capitalizable trimestralmente, 5.5 años
A5: Principal (USD) | B5: 45000
A6: Tasa anual | B6: 0.075
A7: Capitalizaciones por año | B7: 4
A8: Años | B8: 5.5
A9: Valor futuro (USD) | B9: =B5*(1+B6/B7)^(B7*B8) -> 67717.387 | F9: VF = P × (1 + i/m)^(m·n), 22 trimestres
A11: Ejercicio 2 · VP de $125,000 MXN a pagar en 48 meses, 12 % anual compuesto mensual
A12: Valor futuro (MXN) | B12: 125000
A13: Tasa anual | B13: 0.12
A14: Meses | B14: 48
A15: Valor presente (MXN) | B15: =B12/(1+B13/12)^B14 -> 77532.551 | F15: VP = VF / (1 + 0.01)^48
A17: Ejercicio 3 · Flujos irregulares al 9 %: año 1 $10,000; año 3 $15,000; año 5 $8,000
A18: Tasa | B18: 0.09
A19: VP año 1 | B19: =10000/(1+B18)^1 -> 9174.3119
A20: VP año 3 | B20: =15000/(1+B18)^3 -> 11582.752
A21: VP año 5 | B21: =8000/(1+B18)^5 -> 5199.4511
A22: Valor presente total | B22: =SUM(B19:B21) -> 25956.515
A24: Ejercicio 4 · InnovaTech: inversión USD 250,000, USD 60,000 al año por 6 años, 11 %
A25: Inversión (USD) | B25: 250000
A26: Flujo anual (USD) | B26: 60000
A27: Tasa | B27: 0.11
A28: Años | B28: 6
A29: Factor de anualidad [1 − (1 + r)^−n] / r | B29: =(1-(1+B27)^-B28)/B27 -> 4.2305379
A30: VPN (USD) | B30: =-B25+B26*B29 -> 3832.2712 | F30: Positivo → viable
A31: Comprobación con la función VNA | B31: =-B25+NPV(B27,B26,B26,B26,B26,B26,B26) -> 3832.2712
A32: TIR | B32: =IRR({-250000,60000,60000,60000,60000,60000,60000}) -> 0.11530473
A34: Ejercicio 5 · Inversión USD 50,000; flujos 7,500 / 12,000 / 20,000 / 25,000; tasa 4 %
A35: Tasa | B35: 0.04
A36: VP año 1 (7,500) | B36: =7500/(1+B35)^1 -> 7211.5385
A37: VP año 2 (12,000) | B37: =12000/(1+B35)^2 -> 11094.675
A38: VP año 3 (20,000) | B38: =20000/(1+B35)^3 -> 17779.927
A39: VP año 4 (25,000) | B39: =25000/(1+B35)^4 -> 21370.105
A40: VPN (USD) | B40: =-50000+SUM(B36:B39) -> 7456.245 | F40: Positivo, pero por poco
A42: Ejercicio 6 · Maquinaria: USD 1,000,000; 300K / 350K / 375K / 300K + salvamento 150K; 10 %
A43: Tasa | B43: 0.1
A44: VP año 1 (300,000) | B44: =300000/(1+B43)^1 -> 272727.27
A45: VP año 2 (350,000) | B45: =350000/(1+B43)^2 -> 289256.2
A46: VP año 3 (375,000) | B46: =375000/(1+B43)^3 -> 281743.05
A47: VP año 4 (450,000) = 300K + 150K de salvamento | B47: =450000/(1+B43)^4 -> 307356.05
...
